Workbook

Sheet Posts
A1: Post ID | B1: Platform | C1: Date | D1: Content Type | E1: Post Text | F1: Likes | G1: Shares | H1: Comments | I1: Impressions | J1: Reach | K1: Clicks | L1: Hashtags Used | M1: Hashtags Used2 | N1: Hashtags Used3 | O1: Campaign_Name | P1: Engagement_Rate
A2: P001 | B2: Twitter | C2: 45649 | D2: Reel | E2: Check out our latest reel on twitter! | F2: 1461 | G2: 184 | H2: 344 | I2: 21915 | J2: 21675 | K2: 15 | L2: #FutureOfDriving | M2: #AnytimeIsTeslaTime | N2: NA | O2: CybertruckLaunch | P2: =(F2+G2+H2)/I2 -> 0.090759754
A3: P002 | B3: Twitter | C3: 45750 | D3: Text | E3: Check out our latest text on twitter! | F3: 4054 | G3: 389 | H3: 493 | I3: 64864 | J3: 64383 | K3: 117 | L3: #TeslaCoInnovation | M3: #BetterWithTesla | N3: NA | O3: ModelYCampaign | P3: =(F3+G3+H3)/I3 -> 0.076097681
A4: P003 | B4: YouTube | C4: 45789 | D4: Reel | E4: Check out our latest reel on youtube! | F4: 2795 | G4: 105 | H4: 49 | I4: 53105 | J4: 52307 | K4: 204 | L4: #TeslaCoInnovation | M4: NA | N4: NA | O4: FSDUpdate | P4: =(F4+G4+H4)/I4 -> 0.055531494
A5: P004 | B5: Instagram | C5: 45516 | D5: Story | E5: Check out our latest story on instagram! | F5: 2404 | G5: 363 | H5: 138 | I5: 19232 | J5: 18636 | K5: 128 | L5: #EVRevolution | M5: NA | N5: NA | O5: SustainabilityDrive | P5: =(F5+G5+H5)/I5 -> 0.15105033
A6: P005 | B6: YouTube | C6: 45469 | D6: Reel | E6: Check out our latest reel on youtube! | F6: 3557 | G6: 687 | H6: 424 | I6: 71140 | J6: 70701 | K6: 224 | L6: #EVRevolution | M6: #TeslaCoInnovation | N6: NA | O6: CybertruckLaunch | P6: =(F6+G6+H6)/I6 -> 0.065617093
A7: P006 | B7: Facebook | C7: 45596 | D7: Carousel | E7: Check out our latest carousel on facebook! | F7: 2945 | G7: 930 | H7: 355 | I7: 23560 | J7: 23275 | K7: 256 | L7: #TeslaCoInnovation | M7: NA | N7: NA | O7: ModelYCampaign | P7: =(F7+G7+H7)/I7 -> 0.1795416
A8: P007 | B8: Twitter | C8: 45467 | D8: Carousel | E8: Check out our latest carousel on twitter! | F8: 3860 | G8: 201 | H8: 279 | I8: 61760 | J8: 61660 | K8: 235 | L8: #TeslaCoInnovation | M8: NA | N8: NA | O8: ModelYCampaign | P8: =(F8+G8+H8)/I8 -> 0.070272021
A9: P008 | B9: YouTube | C9: 45486 | D9: Image | E9: Check out our latest image on youtube! | F9: 3929 | G9: 262 | H9: 278 | I9: 43219 | J9: 42841 | K9: 39 | L9: #EVRevolution | M9: NA | N9: NA | O9: SustainabilityDrive | P9: =(F9+G9+H9)/I9 -> 0.1034036
A10: P009 | B10: Facebook | C10: 45534 | D10: Text | E10: Check out our latest text on facebook! | F10: 3784 | G10: 808 | H10: 404 | I10: 56760 | J10: 56343 | K10: 131 | L10: #TeslaCoInnovation | M10: NA | N10: NA | O10: ModelYCampaign | P10: =(F10+G10+H10)/I10 -> 0.088019732
A11: P010 | B11: Facebook | C11: 45727 | D11: Image | E11: Check out our latest image on facebook! | F11: 4241 | G11: 902 | H11: 47 | I11: 72097 | J11: 71598 | K11: 167 | L11: #TeslaCoInnovation | M11: NA | N11: NA | O11: ModelYCampaign | P11: =(F11+G11+H11)/I11 -> 0.071986352
A12: P011 | B12: Instagram | C12: 45690 | D12: Story | E12: Check out our latest story on instagram! | F12: 1792 | G12: 614 | H12: 497 | I12: 25088 | J12: 24675 | K12: 65 | L12: #FutureOfDriving | M12: NA | N12: NA | O12: SustainabilityDrive | P12: =(F12+G12+H12)/I12 -> 0.11571269
A13: P012 | B13: Facebook | C13: 45494 | D13: Reel | E13: Check out our latest reel on facebook! | F13: 1946 | G13: 686 | H13: 377 | I13: 23352 | J13: 22982 | K13: 213 | L13: #FutureOfDriving | M13: NA | N13: NA | O13: FSDUpdate | P13: =(F13+G13+H13)/I13 -> 0.12885406
A14: P013 | B14: YouTube | C14: 45614 | D14: Carousel | E14: Check out our latest carousel on youtube! | F14: 1171 | G14: 286 | H14: 231 | I14: 22249 | J14: 21282 | K14: 114 | L14: #EVRevolution | M14: NA | N14: NA | O14: CybertruckLaunch | P14: =(F14+G14+H14)/I14 -> 0.075868578
A15: P014 | B15: Facebook | C15: 45704 | D15: Story | E15: Check out our latest story on facebook! | F15: 4242 | G15: 555 | H15: 131 | I15: 33936 | J15: 33802 | K15: 265 | L15: #FutureOfDriving | M15: NA | N15: NA | P15: =(F15+G15+H15)/I15 -> 0.14521452
A16: P015 | B16: Facebook | C16: 45589 | D16: Video | E16: Check out our latest video on facebook! | F16: 3888 | G16: 604 | H16: 128 | I16: 77760 | J16: 77167 | K16: 20 | L16: #FutureOfDriving | M16: NA | N16: NA | O16: CybertruckLaunch | P16: =(F16+G16+H16)/I16 -> 0.05941358
A17: P016 | B17: Facebook | C17: 45530 | D17: Text | E17: Check out our latest text on facebook! | F17: 3452 | G17: 377 | H17: 360 | I17: 55232 | J17: 55075 | K17: 87 | L17: #FutureOfDriving | M17: NA | N17: NA | O17: FSDUpdate | P17: =(F17+G17+H17)/I17 -> 0.075843714
A18: P017 | B18: Facebook | C18: 45782 | D18: Text | E18: Check out our latest text on facebook! | F18: 4441 | G18: 511 | H18: 70 | I18: 53292 | J18: 53082 | K18: 159 | L18: #EVRevolution | M18: NA | N18: NA | O18: SustainabilityDrive | P18: =(F18+G18+H18)/I18 -> 0.094235533
A19: P018 | B19: Instagram | C19: 45523 | D19: Reel | E19: Check out our latest reel on instagram! | F19: 3000 | G19: 382 | H19: 325 | I19: 36000 | J19: 35819 | K19: 19 | L19: #FutureOfDriving | M19: NA | N19: NA | O19: CybertruckLaunch | P19: =(F19+G19+H19)/I19 -> 0.10297222
A20: P019 | B20: Instagram | C20: 45466 | D20: Video | E20: Check out our latest video on instagram! | F20: 1071 | G20: 519 | H20: 22 | I20: 16065 | J20: 15865 | K20: 103 | L20: #TeslaCoInnovation | M20: NA | N20: NA | O20: SustainabilityDrive | P20: =(F20+G20+H20)/I20 -> 0.10034236
A21: P020 | B21: Instagram | C21: 45544 | D21: Carousel | E21: Check out our latest carousel on instagram! | F21: 4054 | G21: 488 | H21: 373 | I21: 77026 | J21: 76881 | K21: 25 | L21: #TeslaCoInnovation | M21: NA | N21: NA | O21: CybertruckLaunch | P21: =(F21+G21+H21)/I21 -> 0.063809623
A22: P021 | B22: Instagram | C22: 45661 | D22: Reel | E22: Check out our latest reel on instagram! | F22: 4838 | G22: 640 | H22: 128 | I22: 72570 | J22: 72396 | K22: 83 | L22: #FutureOfDriving | M22: NA | N22: NA | O22: SustainabilityDrive | P22: =(F22+G22+H22)/I22 -> 0.077249552
A23: P022 | B23: Facebook | C23: 45715 | D23: Text | E23: Check out our latest text on facebook! | F23: 1570 | G23: 187 | H23: 260 | I23: 25120 | J23: 24613 | K23: 133 | L23: #TeslaCoInnovation | M23: NA | N23: NA | O23: SustainabilityDrive | P23: =(F23+G23+H23)/I23 -> 0.080294586
A24: P023 | B24: Facebook | C24: 45602 | D24: Video | E24: Check out our latest video on facebook! | F24: 1606 | G24: 547 | H24: 316 | I24: 32120 | J24: 31736 | K24: 225 | L24: #TeslaCoInnovation | M24: #AnytimeIsTeslaTime | N24: NA | O24: ModelYCampaign | P24: =(F24+G24+H24)/I24 -> 0.076867995
A25: P024 | B25: Facebook | C25: 45680 | D25: Video | E25: Check out our latest video on facebook! | F25: 3961 | G25: 761 | H25: 131 | I25: 67337 | J25: 66615 | K25: 161 | L25: #FutureOfDriving | M25: NA | N25: NA | O25: FSDUpdate | P25: =(F25+G25+H25)/I25 -> 0.072070333
A26: P025 | B26: Twitter | C26: 45757 | D26: Carousel | E26: Check out our latest carousel on twitter! | F26: 3128 | G26: 211 | H26: 197 | I26: 59432 | J26: 59182 | K26: 238 | L26: #EVRevolution | M26: NA | N26: NA | P26: =(F26+G26+H26)/I26 -> 0.059496568
A27: P026 | B27: YouTube | C27: 45752 | D27: Reel | E27: Check out our latest reel on youtube! | F27: 3009 | G27: 413 | H27: 358 | I27: 42126 | J27: 41309 | K27: 211 | L27: #FutureOfDriving | M27: NA | N27: NA | O27: ModelYCampaign | P27: =(F27+G27+H27)/I27 -> 0.089730808
A28: P027 | B28: YouTube | C28: 45552 | D28: Text | E28: Check out our latest text on youtube! | F28: 2076 | G28: 195 | H28: 104 | I28: 33216 | J28: 32244 | K28: 51 | L28: #FutureOfDriving | M28: NA | N28: NA | O28: SustainabilityDrive | P28: =(F28+G28+H28)/I28 -> 0.071501686
A29: P028 | B29: Instagram | C29: 45720 | D29: Video | E29: Check out our latest video on instagram! | F29: 432 | G29: 624 | H29: 123 | I29: 6912 | J29: 6259 | K29: 79 | L29: #FutureOfDriving | M29: NA | N29: NA | O29: SustainabilityDrive | P29: =(F29+G29+H29)/I29 -> 0.17057292
A30: P029 | B30: Instagram | C30: 45688 | D30: Carousel | E30: Check out our latest carousel on instagram! | F30: 2566 | G30: 118 | H30: 37 | I30: 12830 | J30: 12264 | K30: 221 | L30: #FutureOfDriving | M30: NA | N30: NA | O30: FSDUpdate | P30: =(F30+G30+H30)/I30 -> 0.21208106
A31: P030 | B31: Instagram | C31: 45713 | D31: Video | E31: Check out our latest video on instagram! | F31: 3095 | G31: 39 | H31: 78 | I31: 55710 | J31: 54808 | K31: 93 | L31: #EVRevolution | M31: NA | N31: NA | P31: =(F31+G31+H31)/I31 -> 0.057655717
A32: P031 | B32: Instagram | C32: 45642 | D32: Text | E32: Check out our latest text on instagram! | F32: 438 | G32: 153 | H32: 275 | I32: 3066 | J32: 2701 | K32: 282 | L32: #TeslaCoInnovation | M32: NA | N32: NA | O32: ModelYCampaign | P32: =(F32+G32+H32)/I32 -> 0.28245271
A33: P032 | B33: Twitter | C33: 45504 | D33: Carousel | E33: Check out our latest carousel on twitter! | F33: 2278 | G33: 10 | H33: 321 | I33: 13668 | J33: 12676 | K33: 275 | L33: #EVRevolution | M33: NA | N33: NA | O33: CybertruckLaunch | P33: =(F33+G33+H33)/I33 -> 0.19088382
A34: P033 | B34: Facebook | C34: 45525 | D34: Image | E34: Check out our latest image on facebook! | F34: 1407 | G34: 400 | H34: 351 | I34: 16884 | J34: 15954 | K34: 113 | L34: #TeslaCoInnovation | M34: NA | N34: NA | O34: CybertruckLaunch | P34: =(F34+G34+H34)/I34 -> 0.12781331
A35: P034 | B35: Facebook | C35: 45742 | D35: Text | E35: Check out our latest text on facebook! | F35: 1652 | G35: 89 | H35: 357 | I35: 29736 | J35: 28771 | K35: 215 | L35: #TeslaCoInnovation | M35: NA | N35: NA | O35: FSDUpdate | P35: =(F35+G35+H35)/I35 -> 0.07055421
A36: P035 | B36: Instagram | C36: 45626 | D36: Video | E36: Check out our latest video on instagram! | F36: 3775 | G36: 16 | H36: 239 | I36: 33975 | J36: 33310 | K36: 271 | L36: #FutureOfDriving | M36: NA | N36: NA | O36: ModelYCampaign | P36: =(F36+G36+H36)/I36 -> 0.11861663
A37: P036 | B37: Instagram | C37: 45766 | D37: Story | E37: Check out our latest story on instagram! | F37: 4518 | G37: 285 | H37: 383 | I37: 67770 | J37: 67621 | K37: 31 | L37: #EVRevolution | M37: NA | N37: NA | O37: ModelYCampaign | P37: =(F37+G37+H37)/I37 -> 0.076523535
A38: P037 | B38: Facebook | C38: 45663 | D38: Carousel | E38: Check out our latest carousel on facebook! | F38: 3024 | G38: 925 | H38: 350 | I38: 24192 | J38: 23518 | K38: 36 | L38: #EVRevolution | M38: NA | N38: NA | O38: ModelYCampaign | P38: =(F38+G38+H38)/I38 -> 0.17770337
A39: P038 | B39: YouTube | C39: 45705 | D39: Reel | E39: Check out our latest reel on youtube! | F39: 3138 | G39: 123 | H39: 291 | I39: 28242 | J39: 27550 | K39: 87 | L39: #TeslaCoInnovation | M39: NA | N39: NA | O39: SustainabilityDrive | P39: =(F39+G39+H39)/I39 -> 0.12577013
A40: P039 | B40: Facebook | C40: 45621 | D40: Image | E40: Check out our latest image on facebook! | F40: 3564 | G40: 629 | H40: 177 | I40: 60588 | J40: 59627 | K40: 92 | L40: #TeslaCoInnovation | M40: NA | N40: NA | P40: =(F40+G40+H40)/I40 -> 0.072126494
...

Sheet Engagement Summary
A1: Week_Start_Date | B1: Platform | C1: New_Followers | D1: Unfollows | E1: Total_Followers | F1: Follower_Growth_Rate | G1: Engagement_Rate | H1: Week_Start_Date2 | I1: Engagement | J1: Ad_Spend | K1: Net_Followers | L1: ROI | M1: Campaign_Name
A2: 45446 | B2: Instagram | C2: 1135 | D2: 88 | E2: 344084 | F2: =((C2-D2)/E2)*100 -> 0.30428616 | G2: 8.06 | H2: 45446 | I2: =G2*100 -> 806 | J2: 5904 | K2: =(C2-D2) -> 1047 | L2: =(G2/J2)*100 -> 0.13651762 | M2: =VLOOKUP(B2,Posts!B:O,14,FALSE) -> SustainabilityDrive
A3: 45446 | B3: Facebook | C3: 1312 | D3: 310 | E3: 42654 | F3: =((C3-D3)/E3)*100 -> 2.3491349 | G3: 4.98 | H3: 45446 | I3: =G3*100 -> 498 | J3: 9566 | K3: =(C3-D3) -> 1002 | L3: =(G3/J3)*100 -> 0.052059377 | M3: =VLOOKUP(B3,Posts!B:O,14,FALSE) -> ModelYCampaign
A4: 45446 | B4: Twitter | C4: 584 | D4: 169 | E4: 146834 | F4: =((C4-D4)/E4)*100 -> 0.28263209 | G4: 8.31 | H4: 45446 | I4: =G4*100 -> 831 | J4: 26752 | K4: =(C4-D4) -> 415 | L4: =(G4/J4)*100 -> 0.031063098 | M4: =VLOOKUP(B4,Posts!B:O,14,FALSE) -> CybertruckLaunch
A5: 45446 | B5: YouTube | C5: 1535 | D5: 445 | E5: 395536 | F5: =((C5-D5)/E5)*100 -> 0.27557542 | G5: 4.11 | H5: 45446 | I5: =G5*100 -> 411 | J5: 30671 | K5: =(C5-D5) -> 1090 | L5: =(G5/J5)*100 -> 0.01340028 | M5: =VLOOKUP(B5,Posts!B:O,14,FALSE) -> FSDUpdate
A6: 45453 | B6: Instagram | C6: 656 | D6: 139 | E6: 49157 | F6: =((C6-D6)/E6)*100 -> 1.0517322 | G6: 9.05 | H6: 45453 | I6: =G6*100 -> 905 | J6: 9920 | K6: =(C6-D6) -> 517 | L6: =(G6/J6)*100 -> 0.091229839 | M6: =VLOOKUP(B6,Posts!B:O,14,FALSE) -> SustainabilityDrive
A7: 45453 | B7: Facebook | C7: 1697 | D7: 414 | E7: 316555 | F7: =((C7-D7)/E7)*100 -> 0.40530082 | G7: 2.37 | H7: 45453 | I7: =G7*100 -> 237 | J7: 7924 | K7: =(C7-D7) -> 1283 | L7: =(G7/J7)*100 -> 0.029909137 | M7: =VLOOKUP(B7,Posts!B:O,14,FALSE) -> ModelYCampaign
A8: 45453 | B8: Twitter | C8: 436 | D8: 250 | E8: 254347 | F8: =((C8-D8)/E8)*100 -> 0.073128443 | G8: 4.01 | H8: 45453 | I8: =G8*100 -> 401 | J8: 8912 | K8: =(C8-D8) -> 186 | L8: =(G8/J8)*100 -> 0.044995512 | M8: =VLOOKUP(B8,Posts!B:O,14,FALSE) -> CybertruckLaunch
A9: 45453 | B9: YouTube | C9: 1197 | D9: 203 | E9: 413878 | F9: =((C9-D9)/E9)*100 -> 0.24016739 | G9: 3.16 | H9: 45453 | I9: =G9*100 -> 316 | J9: 21205 | K9: =(C9-D9) -> 994 | L9: =(G9/J9)*100 -> 0.014902146 | M9: =VLOOKUP(B9,Posts!B:O,14,FALSE) -> FSDUpdate
A10: 45460 | B10: Instagram | C10: 1048 | D10: 155 | E10: 456946 | F10: =((C10-D10)/E10)*100 -> 0.19542791 | G10: 2.46 | H10: 45460 | I10: =G10*100 -> 246 | J10: 11329 | K10: =(C10-D10) -> 893 | L10: =(G10/J10)*100 -> 0.021714185 | M10: =VLOOKUP(B10,Posts!B:O,14,FALSE) -> SustainabilityDrive
A11: 45460 | B11: Facebook | C11: 1753 | D11: 371 | E11: 169496 | F11: =((C11-D11)/E11)*100 -> 0.81535847 | G11: 8.11 | H11: 45460 | I11: =G11*100 -> 811 | J11: 46670 | K11: =(C11-D11) -> 1382 | L11: =(G11/J11)*100 -> 0.01737733 | M11: =VLOOKUP(B11,Posts!B:O,14,FALSE) -> ModelYCampaign
A12: 45460 | B12: Twitter | C12: 1335 | D12: 40 | E12: 122732 | F12: =((C12-D12)/E12)*100 -> 1.0551445 | G12: 8.19 | H12: 45460 | I12: =G12*100 -> 819 | J12: 22482 | K12: =(C12-D12) -> 1295 | L12: =(G12/J12)*100 -> 0.036429143 | M12: =VLOOKUP(B12,Posts!B:O,14,FALSE) -> CybertruckLaunch
A13: 45460 | B13: YouTube | C13: 403 | D13: 66 | E13: 382851 | F13: =((C13-D13)/E13)*100 -> 0.0880238 | G13: 3.49 | H13: 45460 | I13: =G13*100 -> 349 | J13: 24313 | K13: =(C13-D13) -> 337 | L13: =(G13/J13)*100 -> 0.014354461 | M13: =VLOOKUP(B13,Posts!B:O,14,FALSE) -> FSDUpdate
... A201: 45789 | B201: YouTube | C201: 119 | D201: 456 | E201: 82558 | F201: =((C201-D201)/E201)*100 -> -0.40819787 | G201: 6.81 | H201: 45789 | I201: =G201*100 -> 681 | J201: 12174 | K201: =(C201-D201) -> -337 | L201: =(G201/J201)*100 -> 0.055938886 | M201: =VLOOKUP(B201,Posts!B:O,14,FALSE) -> FSDUpdate

Sheet Campaign Metadata
A1: Campaign_Name | B1: Start_Date | C1: End_Date | D1: Objective | E1: Total_Budget | F1: Target_Platforms | G1: Primary_Hashtags
A2: CybertruckLaunch | B2: 2024-06-15 | C2: 2024-07-15 | D2: Product Awareness | E2: 150000 | F2: Instagram,Facebook | G2: #EVRevolution,#TeslaCoInnovation
A3: ModelYCampaign | B3: 2024-10-01 | C3: 2024-10-31 | D3: Customer Engagement | E3: 200000 | F3: Instagram,YouTube | G3: #AnytimeIsTeslaTime,
A4: FSDUpdate | B4: 2024-12-25 | C4: 2025-01-10 | D4: Vehicle Launch | E4: 250000 | F4: Facebook,Twitter | G4: #SmoothLikeNitroTesla
A5: SustainabilityDrive | B5: 2025-03-01 | C5: 2025-03-31 | D5: Community Growth | E5: 180000 | F5: Instagram,Twitter | G5: #BetterWithTesla,#FutureOfDriving

Sheet Task 2
B3: Column Labels
B4: Sum of Likes | G4: Sum of Shares | L4: Sum of Comments | Q4: Total Sum of Likes | R4: Total Sum of Shares | S4: Total Sum of Comments
A5: Content Type | B5: Facebook | C5: Instagram | D5: Twitter | E5: YouTube | F5: (blank) | G5: Facebook | H5: Instagram | I5: Twitter | J5: YouTube | K5: (blank) | L5: Facebook | M5: Instagram | N5: Twitter | O5: YouTube | P5: (blank)
A6: Carousel | B6: 44476 | C6: 43948 | D6: 48649 | E6: 24926 | G6: 7400 | H6: 6975 | I6: 5791 | J6: 6305 | L6: 4589 | M6: 3890 | N6: 3607 | O6: 2422 | Q6: 161999 | R6: 26471 | S6: 14508
A7: Image | B7: 71602 | C7: 34202 | D7: 43761 | E7: 23903 | G7: 12904 | H7: 5286 | I7: 7110 | J7: 4310 | L7: 6495 | M7: 2655 | N7: 5125 | O7: 2077 | Q7: 173468 | R7: 29610 | S7: 16352
A8: Reel | B8: 36368 | C8: 32148 | D8: 27029 | E8: 32400 | G8: 5964 | H8: 8110 | I8: 4550 | J8: 4577 | L8: 3353 | M8: 3386 | N8: 1913 | O8: 2668 | Q8: 127945 | R8: 23201 | S8: 11320
A9: Story | B9: 29405 | C9: 42649 | D9: 20466 | E9: 31968 | G9: 4950 | H9: 10049 | I9: 5090 | J9: 3866 | L9: 3223 | M9: 3846 | N9: 3026 | O9: 2012 | Q9: 124488 | R9: 23955 | S9: 12107
A10: Text | B10: 31963 | C10: 25567 | D10: 31899 | E10: 27067 | G10: 4792 | H10: 5112 | I10: 4861 | J10: 3928 | L10: 3377 | M10: 1946 | N10: 3910 | O10: 1052 | Q10: 116496 | R10: 18693 | S10: 10285
A11: Video | B11: 28947 | C11: 25770 | D11: 29593 | E11: 31285 | G11: 3171 | H11: 5912 | I11: 6326 | J11: 5586 | L11: 2263 | M11: 2128 | N11: 3299 | O11: 2589 | Q11: 115595 | R11: 20995 | S11: 10279
A12: (blank)
A13: Grand Total | B13: 242761 | C13: 204284 | D13: 201397 | E13: 171549 | G13: 39181 | H13: 41444 | I13: 33728 | J13: 28572 | L13: 23300 | M13: 17851 | N13: 20880 | O13: 12820 | Q13: 819991 | R13: 142925 | S13: 74851

Sheet Task 2.1
A3: Hashtags Used | B3: Average of Clicks
A4: #EVRevolution | B4: 152.86598
A5: #FutureOfDriving | B5: 144.03883
A6: #TeslaCoInnovation | B6: 157.02
A7: (blank)
A8: Grand Total | B8: 151.22

Sheet Task 2.2
A3: Hashtags Used | B3: Count of Engagement Rate
A4: #EVRevolution | B4: 97
A5: #FutureOfDriving | B5: 103
A6: #TeslaCoInnovation | B6: 100
A7: (blank)
A8: (blank)
A9: Grand Total | B9: 300

Sheet Task 3
A3: Platform | B3: Average of Engagement Rate
A4: Facebook | B4: 0.1219729
A5: Instagram | B5: 0.19329258
A6: Twitter | B6: 0.14368407
A7: YouTube | B7: 0.13118494
A8: (blank)
A9: Grand Total | B9: 0.14828272

Sheet Task 3.1
A3: Platform | B3: Average of Follower_Growth_Rate
A4: Facebook | B4: 0.54649907
A5: Instagram | B5: 0.57625321
A6: Twitter | B6: 0.92800257
A7: YouTube | B7: 0.90210666
A8: Grand Total | B8: 0.73821538

Sheet Task 3.2
B3: Values
A4: Platform | B4: Sum of Engagement | C4: Sum of Ad_Spend
A5: Facebook | B5: 28243 | C5: 1379539
A6: Instagram | B6: 28578 | C6: 1164373
A7: Twitter | B7: 28279 | C7: 1060357
A8: YouTube | B8: 27794 | C8: 1228647
A9: (blank)
A10: Grand Total | B10: 112894 | C10: 4832916

Sheet Task 4
B5: Values
A6: Hashtags Used | B6: Count of Hashtags Used | C6: Count of Hashtags Used2 | D6: Count of Hashtags Used3
A7: #EVRevolution | B7: 97 | C7: 9 | D7: 4
A8: #FutureOfDriving | B8: 103 | C8: 8 | D8: 5
A9: #TeslaCoInnovation | B9: 100 | C9: 11 | D9: 2
A10: (blank)
A11: Grand Total | B11: 300 | C11: 28 | D11: 11

Sheet Task 4.1
A3: Hashtags Used | B3: Average of Engagement Rate
A4: #EVRevolution | B4: 0.15664344
A5: #AnytimeIsTeslaTime | B5: 0.21636759
A6: #BetterWithTesla | B6: 0.21758378
A7: #EVRevolution | B7: 0.079915049
A8: #SmoothLikeNitroTesla | B8: 0.15571803
A9: #TeslaCoInnovation | B9: 0.10006593
A10: (blank) | B10: 0.15803389
A11: #FutureOfDriving | B11: 0.14123247
A12: #AnytimeIsTeslaTime | B12: 0.10098269
A13: #EVRevolution | B13: 0.1187991
A14: #SmoothLikeNitroTesla | B14: 0.11143487
A15: #TeslaCoInnovation | B15: 0.1292236
... A22: (blank) | B22: 0.15376805
A23: (blank)
A24: (blank)
A25: Grand Total | B25: 0.14828272

Sheet Task 4.2
A3: Content Type | B3: Average of Engagement Rate
A4: Carousel | B4: 0.1481492
A5: Image | B5: 0.13687494
A6: Video | B6: 0.14814844
A7: Grand Total | B7: 0.14384429

Sheet Task 4.3
A3: Average of Engagement Rate | B3: Column Labels
A4: Platform | B4: Carousel | C4: Image | D4: Reel | E4: Story | F4: Text | G4: Video | H4: (blank) | I4: Grand Total
A5: Facebook | B5: 0.1182059 | C5: 0.11892683 | D5: 0.10810248 | E5: 0.15898978 | F5: 0.10743951 | G5: 0.12899654 | I5: 0.1219729
A6: Instagram | B6: 0.1443986 | C6: 0.14929862 | D6: 0.26004033 | E6: 0.24558274 | F6: 0.12920449 | G6: 0.20623961 | I6: 0.19329258
A7: Twitter | B7: 0.15972488 | C7: 0.14756648 | D7: 0.12428082 | E7: 0.18859717 | F7: 0.12088973 | G7: 0.11980877 | I7: 0.14368407
A8: YouTube | B8: 0.17416554 | C8: 0.15035568 | D8: 0.11688584 | E8: 0.09496533 | F8: 0.11459218 | G8: 0.12968338 | I8: 0.13118494
A9: (blank)
A10: Grand Total | B10: 0.1481492 | C10: 0.13687494 | D10: 0.15615682 | E10: 0.18425775 | F10: 0.11750674 | G10: 0.14814844 | I10: 0.14828272

Sheet Task 5
B3: Values
A4: Campaign_Name | B4: Sum of Impressions | C4: Average of Impressions | D4: Sum of Likes | E4: Average of Likes | F4: Sum of Clicks | G4: Average of Clicks
A5: CybertruckLaunch | B5: 1846272 | C5: 38464 | D5: 138793 | E5: 2891.5208 | F5: 6434 | G5: 134.04167
A6: FSDUpdate | B6: 2266053 | C6: 33821.687 | D6: 183346 | E6: 2736.5075 | F6: 10032 | G6: 149.73134
A7: ModelYCampaign | B7: 1986356 | C7: 34247.517 | D7: 159783 | E7: 2754.8793 | F7: 9872 | G7: 170.2069
A8: SustainabilityDrive | B8: 2464864 | C8: 34716.394 | D8: 187909 | E8: 2646.6056 | F8: 10689 | G8: 150.5493
A9: (blank) | B9: 1830608 | C9: 32689.429 | D9: 150160 | E9: 2681.4286 | F9: 8339 | G9: 148.91071
A10: Grand Total | B10: 10394153 | C10: 34647.177 | D10: 819991 | E10: 2733.3033 | F10: 45366 | G10: 151.22

Sheet Task 5.1
A1: Post ID | B1: Platform | C1: Date | D1: Content Type | E1: Likes | F1: Shares | G1: Comments | H1: Impressions | I1: Reach | J1: Clicks | K1: Hashtags Used | L1: Hashtags Used2 | M1: Hashtags Used3 | N1: Campaign_Name | O1: Engagement | P1: Period | Q1: AVG_Before | R1: AVG_During | S1: Uplift% | V1: Campaign_Name | W1: Start_Date | X1: End_Date
A2: P001 | B2: Twitter | C2: 45649 | D2: Reel | E2: 1461 | F2: 184 | G2: 344 | H2: 21915 | I2: 21675 | J2: 15 | K2: #FutureOfDriving | L2: #AnytimeIsTeslaTime | M2: NA | N2: CybertruckLaunch | O2: =((E2+F2+G2)/H2)*100 -> 9.0759754 | P2: =IF(AND(C2>=$W$2,C2<=$X$2),"During","Before") -> Before | Q2: =AVERAGEIF(P2:P301,"Before",O2) -> 15.27214 | R2: =AVERAGEIF(P2:P301,"During",O2) -> 10.340277 | S2: =(R2-Q2)/Q2 -> -0.32293201 | V2: CybertruckLaunch | W2: 45458 | X2: 45488
A3: P002 | B3: Twitter | C3: 45750 | D3: Text | E3: 4054 | F3: 389 | G3: 493 | H3: 64864 | I3: 64383 | J3: 117 | K3: #TeslaCoInnovation | L3: #BetterWithTesla | M3: NA | N3: ModelYCampaign | O3: =((E3+F3+G3)/H3)*100 -> 7.6097681 | P3: =IF(AND(C3>=$W$2,C3<=$X$2),"During","Before") -> Before | Q3: =AVERAGEIF(P3:P302,"Before",O3) -> 15.29492 | R3: =AVERAGEIF(P3:P302,"During",O3) -> 10.340277 | S3: =(R3-Q3)/Q3 -> -0.32394043 | V3: ModelYCampaign | W3: 45566 | X3: 45596
A4: P003 | B4: YouTube | C4: 45789 | D4: Reel | E4: 2795 | F4: 105 | G4: 49 | H4: 53105 | I4: 52307 | J4: 204 | K4: #TeslaCoInnovation | L4: NA | M4: NA | N4: FSDUpdate | O4: =((E4+F4+G4)/H4)*100 -> 5.5531494 | P4: =IF(AND(C4>=$W$2,C4<=$X$2),"During","Before") -> Before | Q4: =AVERAGEIF(P4:P303,"Before",O4) -> 15.323279 | R4: =AVERAGEIF(P4:P303,"During",O4) -> 10.340277 | S4: =(R4-Q4)/Q4 -> -0.3251916 | V4: FSDUpdate | W4: 45651 | X4: 45667
A5: P004 | B5: Instagram | C5: 45516 | D5: Story | E5: 2404 | F5: 363 | G5: 138 | H5: 19232 | I5: 18636 | J5: 128 | K5: #EVRevolution | L5: NA | M5: NA | N5: SustainabilityDrive | O5: =((E5+F5+G5)/H5)*100 -> 15.105033 | P5: =IF(AND(C5>=$W$2,C5<=$X$2),"During","Before") -> Before | Q5: =AVERAGEIF(P5:P304,"Before",O5) -> 15.359464 | R5: =AVERAGEIF(P5:P304,"During",O5) -> 10.340277 | S5: =(R5-Q5)/Q5 -> -0.32678139 | V5: SustainabilityDrive | W5: 45717 | X5: 45747
A6: P005 | B6: YouTube | C6: 45469 | D6: Reel | E6: 3557 | F6: 687 | G6: 424 | H6: 71140 | I6: 70701 | J6: 224 | K6: #EVRevolution | L6: #TeslaCoInnovation | M6: NA | N6: CybertruckLaunch | O6: =((E6+F6+G6)/H6)*100 -> 6.5617093 | P6: =IF(AND(C6>=$W$2,C6<=$X$2),"During","Before") -> During | Q6: =AVERAGEIF(P6:P305,"Before",O6) -> 15.36041 | R6: =AVERAGEIF(P6:P305,"During",O6) -> 10.340277 | S6: =(R6-Q6)/Q6 -> -0.32682285
A7: P006 | B7: Facebook | C7: 45596 | D7: Carousel | E7: 2945 | F7: 930 | G7: 355 | H7: 23560 | I7: 23275 | J7: 256 | K7: #TeslaCoInnovation | L7: NA | M7: NA | N7: ModelYCampaign | O7: =((E7+F7+G7)/H7)*100 -> 17.95416 | P7: =IF(AND(C7>=$W$2,C7<=$X$2),"During","Before") -> Before | Q7: =AVERAGEIF(P7:P306,"Before",O7) -> 15.36041 | R7: =AVERAGEIF(P7:P306,"During",O7) -> 10.485607 | S7: =(R7-Q7)/Q7 -> -0.31736154
A8: P007 | B8: Twitter | C8: 45467 | D8: Carousel | E8: 3860 | F8: 201 | G8: 279 | H8: 61760 | I8: 61660 | J8: 235 | K8: #TeslaCoInnovation | L8: NA | M8: NA | N8: ModelYCampaign | O8: =((E8+F8+G8)/H8)*100 -> 7.0272021 | P8: =IF(AND(C8>=$W$2,C8<=$X$2),"During","Before") -> During | Q8: =AVERAGEIF(P8:P307,"Before",O8) -> 15.350732 | R8: =AVERAGEIF(P8:P307,"During",O8) -> 10.485607 | S8: =(R8-Q8)/Q8 -> -0.31693116
A9: P008 | B9: YouTube | C9: 45486 | D9: Image | E9: 3929 | F9: 262 | G9: 278 | H9: 43219 | I9: 42841 | J9: 39 | K9: #EVRevolution | L9: NA | M9: NA | N9: SustainabilityDrive | O9: =((E9+F9+G9)/H9)*100 -> 10.34036 | P9: =IF(AND(C9>=$W$2,C9<=$X$2),"During","Before") -> During | Q9: =AVERAGEIF(P9:P308,"Before",O9) -> 15.350732 | R9: =AVERAGEIF(P9:P308,"During",O9) -> 10.623943 | S9: =(R9-Q9)/Q9 -> -0.30791946
A10: P009 | B10: Facebook | C10: 45534 | D10: Text | E10: 3784 | F10: 808 | G10: 404 | H10: 56760 | I10: 56343 | J10: 131 | K10: #TeslaCoInnovation | L10: NA | M10: NA | N10: ModelYCampaign | O10: =((E10+F10+G10)/H10)*100 -> 8.8019732 | P10: =IF(AND(C10>=$W$2,C10<=$X$2),"During","Before") -> Before | Q10: =AVERAGEIF(P10:P309,"Before",O10) -> 15.350732 | R10: =AVERAGEIF(P10:P309,"During",O10) -> 10.635759 | S10: =(R10-Q10)/Q10 -> -0.30714973
A11: P010 | B11: Facebook | C11: 45727 | D11: Image | E11: 4241 | F11: 902 | G11: 47 | H11: 72097 | I11: 71598 | J11: 167 | K11: #TeslaCoInnovation | L11: NA | M11: NA | N11: ModelYCampaign | O11: =((E11+F11+G11)/H11)*100 -> 7.1986352 | P11: =IF(AND(C11>=$W$2,C11<=$X$2),"During","Before") -> Before | Q11: =AVERAGEIF(P11:P310,"Before",O11) -> 15.375259 | R11: =AVERAGEIF(P11:P310,"During",O11) -> 10.635759 | S11: =(R11-Q11)/Q11 -> -0.30825499
A12: P011 | B12: Instagram | C12: 45690 | D12: Story | E12: 1792 | F12: 614 | G12: 497 | H12: 25088 | I12: 24675 | J12: 65 | K12: #FutureOfDriving | L12: NA | M12: NA | N12: SustainabilityDrive | O12: =((E12+F12+G12)/H12)*100 -> 11.571269 | P12: =IF(AND(C12>=$W$2,C12<=$X$2),"During","Before") -> Before | Q12: =AVERAGEIF(P12:P311,"Before",O12) -> 15.405998 | R12: =AVERAGEIF(P12:P311,"During",O12) -> 10.635759 | S12: =(R12-Q12)/Q12 -> -0.30963521
A13: P012 | B13: Facebook | C13: 45494 | D13: Reel | E13: 1946 | F13: 686 | G13: 377 | H13: 23352 | I13: 22982 | J13: 213 | K13: #FutureOfDriving | L13: NA | M13: NA | N13: FSDUpdate | O13: =((E13+F13+G13)/H13)*100 -> 12.885406 | P13: =IF(AND(C13>=$W$2,C13<=$X$2),"During","Before") -> Before | Q13: =AVERAGEIF(P13:P312,"Before",O13) -> 15.420469 | R13: =AVERAGEIF(P13:P312,"During",O13) -> 10.635759 | S13: =(R13-Q13)/Q13 -> -0.31028305
A14: P013 | B14: YouTube | C14: 45614 | D14: Carousel | E14: 1171 | F14: 286 | G14: 231 | H14: 22249 | I14: 21282 | J14: 114 | K14: #EVRevolution | L14: NA | M14: NA | N14: CybertruckLaunch | O14: =((E14+F14+G14)/H14)*100 -> 7.5868578 | P14: =IF(AND(C14>=$W$2,C14<=$X$2),"During","Before") -> Before | Q14: =AVERAGEIF(P14:P313,"Before",O14) -> 15.430072 | R14: =AVERAGEIF(P14:P313,"During",O14) -> 10.635759 | S14: =(R14-Q14)/Q14 -> -0.31071228
A15: P014 | B15: Facebook | C15: 45704 | D15: Story | E15: 4242 | F15: 555 | G15: 131 | H15: 33936 | I15: 33802 | J15: 265 | K15: #FutureOfDriving | L15: NA | M15: NA | O15: =((E15+F15+G15)/H15)*100 -> 14.521452 | P15: =IF(AND(C15>=$W$2,C15<=$X$2),"During","Before") -> Before | Q15: =AVERAGEIF(P15:P314,"Before",O15) -> 15.459894 | R15: =AVERAGEIF(P15:P314,"During",O15) -> 10.635759 | S15: =(R15-Q15)/Q15 -> -0.31204191
A16: P015 | B16: Facebook | C16: 45589 | D16: Video | E16: 3888 | F16: 604 | G16: 128 | H16: 77760 | I16: 77167 | J16: 20 | K16: #FutureOfDriving | L16: NA | M16: NA | N16: CybertruckLaunch | O16: =((E16+F16+G16)/H16)*100 -> 5.941358 | P16: =IF(AND(C16>=$W$2,C16<=$X$2),"During","Before") -> Before | Q16: =AVERAGEIF(P16:P315,"Before",O16) -> 15.463476 | R16: =AVERAGEIF(P16:P315,"During",O16) -> 10.635759 | S16: =(R16-Q16)/Q16 -> -0.31220127
A17: P016 | B17: Facebook | C17: 45530 | D17: Text | E17: 3452 | F17: 377 | G17: 360 | H17: 55232 | I17: 55075 | J17: 87 | K17: #FutureOfDriving | L17: NA | M17: NA | N17: FSDUpdate | O17: =((E17+F17+G17)/H17)*100 -> 7.5843714 | P17: =IF(AND(C17>=$W$2,C17<=$X$2),"During","Before") -> Before | Q17: =AVERAGEIF(P17:P316,"Before",O17) -> 15.499959 | R17: =AVERAGEIF(P17:P316,"During",O17) -> 10.635759 | S17: =(R17-Q17)/Q17 -> -0.31382018
A18: P017 | B18: Facebook | C18: 45782 | D18: Text | E18: 4441 | F18: 511 | G18: 70 | H18: 53292 | I18: 53082 | J18: 159 | K18: #EVRevolution | L18: NA | M18: NA | N18: SustainabilityDrive | O18: =((E18+F18+G18)/H18)*100 -> 9.4235533 | P18: =IF(AND(C18>=$W$2,C18<=$X$2),"During","Before") -> Before | Q18: =AVERAGEIF(P18:P317,"Before",O18) -> 15.530403 | R18: =AVERAGEIF(P18:P317,"During",O18) -> 10.635759 | S18: =(R18-Q18)/Q18 -> -0.31516531
A19: P018 | B19: Instagram | C19: 45523 | D19: Reel | E19: 3000 | F19: 382 | G19: 325 | H19: 36000 | I19: 35819 | J19: 19 | K19: #FutureOfDriving | L19: NA | M19: NA | N19: CybertruckLaunch | O19: =((E19+F19+G19)/H19)*100 -> 10.297222 | P19: =IF(AND(C19>=$W$2,C19<=$X$2),"During","Before") -> Before | Q19: =AVERAGEIF(P19:P318,"Before",O19) -> 15.553982 | R19: =AVERAGEIF(P19:P318,"During",O19) -> 10.635759 | S19: =(R19-Q19)/Q19 -> -0.31620347
A20: P019 | B20: Instagram | C20: 45466 | D20: Video | E20: 1071 | F20: 519 | G20: 22 | H20: 16065 | I20: 15865 | J20: 103 | K20: #TeslaCoInnovation | L20: NA | M20: NA | N20: SustainabilityDrive | O20: =((E20+F20+G20)/H20)*100 -> 10.034236 | P20: =IF(AND(C20>=$W$2,C20<=$X$2),"During","Before") -> During | Q20: =AVERAGEIF(P20:P319,"Before",O20) -> 15.574357 | R20: =AVERAGEIF(P20:P319,"During",O20) -> 10.635759 | S20: =(R20-Q20)/Q20 -> -0.31709804
A21: P020 | B21: Instagram | C21: 45544 | D21: Carousel | E21: 4054 | F21: 488 | G21: 373 | H21: 77026 | I21: 76881 | J21: 25 | K21: #TeslaCoInnovation | L21: NA | M21: NA | N21: CybertruckLaunch | O21: =((E21+F21+G21)/H21)*100 -> 6.3809623 | P21: =IF(AND(C21>=$W$2,C21<=$X$2),"During","Before") -> Before | Q21: =AVERAGEIF(P21:P320,"Before",O21) -> 15.574357 | R21: =AVERAGEIF(P21:P320,"During",O21) -> 10.661912 | S21: =(R21-Q21)/Q21 -> -0.31541879
A22: P021 | B22: Instagram | C22: 45661 | D22: Reel | E22: 4838 | F22: 640 | G22: 128 | H22: 72570 | I22: 72396 | J22: 83 | K22: #FutureOfDriving | L22: NA | M22: NA | N22: SustainabilityDrive | O22: =((E22+F22+G22)/H22)*100 -> 7.7249552 | P22: =IF(AND(C22>=$W$2,C22<=$X$2),"During","Before") -> Before | Q22: =AVERAGEIF(P22:P321,"Before",O22) -> 15.610129 | R22: =AVERAGEIF(P22:P321,"During",O22) -> 10.661912 | S22: =(R22-Q22)/Q22 -> -0.31698757
A23: P022 | B23: Facebook | C23: 45715 | D23: Text | E23: 1570 | F23: 187 | G23: 260 | H23: 25120 | I23: 24613 | J23: 133 | K23: #TeslaCoInnovation | L23: NA | M23: NA | N23: SustainabilityDrive | O23: =((E23+F23+G23)/H23)*100 -> 8.0294586 | P23: =IF(AND(C23>=$W$2,C23<=$X$2),"During","Before") -> Before | Q23: =AVERAGEIF(P23:P322,"Before",O23) -> 15.64093 | R23: =AVERAGEIF(P23:P322,"During",O23) -> 10.661912 | S23: =(R23-Q23)/Q23 -> -0.31833262
A24: P023 | B24: Facebook | C24: 45602 | D24: Video | E24: 1606 | F24: 547 | G24: 316 | H24: 32120 | I24: 31736 | J24: 225 | K24: #TeslaCoInnovation | L24: #AnytimeIsTeslaTime | M24: NA | N24: ModelYCampaign | O24: =((E24+F24+G24)/H24)*100 -> 7.6867995 | P24: =IF(AND(C24>=$W$2,C24<=$X$2),"During","Before") -> Before | Q24: =AVERAGEIF(P24:P323,"Before",O24) -> 15.670779 | R24: =AVERAGEIF(P24:P323,"During",O24) -> 10.661912 | S24: =(R24-Q24)/Q24 -> -0.31963102
A25: P024 | B25: Facebook | C25: 45680 | D25: Video | E25: 3961 | F25: 761 | G25: 131 | H25: 67337 | I25: 66615 | J25: 161 | K25: #FutureOfDriving | L25: NA | M25: NA | N25: FSDUpdate | O25: =((E25+F25+G25)/H25)*100 -> 7.2070333 | P25: =IF(AND(C25>=$W$2,C25<=$X$2),"During","Before") -> Before | Q25: =AVERAGEIF(P25:P324,"Before",O25) -> 15.702212 | R25: =AVERAGEIF(P25:P324,"During",O25) -> 10.661912 | S25: =(R25-Q25)/Q25 -> -0.320993
A26: P025 | B26: Twitter | C26: 45757 | D26: Carousel | E26: 3128 | F26: 211 | G26: 197 | H26: 59432 | I26: 59182 | J26: 238 | K26: #EVRevolution | L26: NA | M26: NA | O26: =((E26+F26+G26)/H26)*100 -> 5.9496568 | P26: =IF(AND(C26>=$W$2,C26<=$X$2),"During","Before") -> Before | Q26: =AVERAGEIF(P26:P325,"Before",O26) -> 15.73579 | R26: =AVERAGEIF(P26:P325,"During",O26) -> 10.661912 | S26: =(R26-Q26)/Q26 -> -0.3224419
A27: P026 | B27: YouTube | C27: 45752 | D27: Reel | E27: 3009 | F27: 413 | G27: 358 | H27: 42126 | I27: 41309 | J27: 211 | K27: #FutureOfDriving | L27: NA | M27: NA | N27: ModelYCampaign | O27: =((E27+F27+G27)/H27)*100 -> 8.9730808 | P27: =IF(AND(C27>=$W$2,C27<=$X$2),"During","Before") -> Before | Q27: =AVERAGEIF(P27:P326,"Before",O27) -> 15.774624 | R27: =AVERAGEIF(P27:P326,"During",O27) -> 10.661912 | S27: =(R27-Q27)/Q27 -> -0.3241099
A28: P027 | B28: YouTube | C28: 45552 | D28: Text | E28: 2076 | F28: 195 | G28: 104 | H28: 33216 | I28: 32244 | J28: 51 | K28: #FutureOfDriving | L28: NA | M28: NA | N28: SustainabilityDrive | O28: =((E28+F28+G28)/H28)*100 -> 7.1501686 | P28: =IF(AND(C28>=$W$2,C28<=$X$2),"During","Before") -> Before | Q28: =AVERAGEIF(P28:P327,"Before",O28) -> 15.801722 | R28: =AVERAGEIF(P28:P327,"During",O28) -> 10.661912 | S28: =(R28-Q28)/Q28 -> -0.32526896
A29: P028 | B29: Instagram | C29: 45720 | D29: Video | E29: 432 | F29: 624 | G29: 123 | H29: 6912 | I29: 6259 | J29: 79 | K29: #FutureOfDriving | L29: NA | M29: NA | N29: SustainabilityDrive | O29: =((E29+F29+G29)/H29)*100 -> 17.057292 | P29: =IF(AND(C29>=$W$2,C29<=$X$2),"During","Before") -> Before | Q29: =AVERAGEIF(P29:P328,"Before",O29) -> 15.836328 | R29: =AVERAGEIF(P29:P328,"During",O29) -> 10.661912 | S29: =(R29-Q29)/Q29 -> -0.32674341
A30: P029 | B30: Instagram | C30: 45688 | D30: Carousel | E30: 2566 | F30: 118 | G30: 37 | H30: 12830 | I30: 12264 | J30: 221 | K30: #FutureOfDriving | L30: NA | M30: NA | N30: FSDUpdate | O30: =((E30+F30+G30)/H30)*100 -> 21.208106 | P30: =IF(AND(C30>=$W$2,C30<=$X$2),"During","Before") -> Before | Q30: =AVERAGEIF(P30:P329,"Before",O30) -> 15.831424 | R30: =AVERAGEIF(P30:P329,"During",O30) -> 10.661912 | S30: =(R30-Q30)/Q30 -> -0.32653489
A31: P030 | B31: Instagram | C31: 45713 | D31: Video | E31: 3095 | F31: 39 | G31: 78 | H31: 55710 | I31: 54808 | J31: 93 | K31: #EVRevolution | L31: NA | M31: NA | O31: =((E31+F31+G31)/H31)*100 -> 5.7655717 | P31: =IF(AND(C31>=$W$2,C31<=$X$2),"During","Before") -> Before | Q31: =AVERAGEIF(P31:P330,"Before",O31) -> 15.809744 | R31: =AVERAGEIF(P31:P330,"During",O31) -> 10.661912 | S31: =(R31-Q31)/Q31 -> -0.32561135
A32: P031 | B32: Instagram | C32: 45642 | D32: Text | E32: 438 | F32: 153 | G32: 275 | H32: 3066 | I32: 2701 | J32: 282 | K32: #TeslaCoInnovation | L32: NA | M32: NA | N32: ModelYCampaign | O32: =((E32+F32+G32)/H32)*100 -> 28.245271 | P32: =IF(AND(C32>=$W$2,C32<=$X$2),"During","Before") -> Before | Q32: =AVERAGEIF(P32:P331,"Before",O32) -> 15.850409 | R32: =AVERAGEIF(P32:P331,"During",O32) -> 10.661912 | S32: =(R32-Q32)/Q32 -> -0.32734151
A33: P032 | B33: Twitter | C33: 45504 | D33: Carousel | E33: 2278 | F33: 10 | G33: 321 | H33: 13668 | I33: 12676 | J33: 275 | K33: #EVRevolution | L33: NA | M33: NA | N33: CybertruckLaunch | O33: =((E33+F33+G33)/H33)*100 -> 19.088382 | P33: =IF(AND(C33>=$W$2,C33<=$X$2),"During","Before") -> Before | Q33: =AVERAGEIF(P33:P332,"Before",O33) -> 15.800023 | R33: =AVERAGEIF(P33:P332,"During",O33) -> 10.661912 | S33: =(R33-Q33)/Q33 -> -0.32519643
A34: P033 | B34: Facebook | C34: 45525 | D34: Image | E34: 1407 | F34: 400 | G34: 351 | H34: 16884 | I34: 15954 | J34: 113 | K34: #TeslaCoInnovation | L34: NA | M34: NA | N34: CybertruckLaunch | O34: =((E34+F34+G34)/H34)*100 -> 12.781331 | P34: =IF(AND(C34>=$W$2,C34<=$X$2),"During","Before") -> Before | Q34: =AVERAGEIF(P34:P333,"Before",O34) -> 15.786601 | R34: =AVERAGEIF(P34:P333,"During",O34) -> 10.661912 | S34: =(R34-Q34)/Q34 -> -0.32462271
A35: P034 | B35: Facebook | C35: 45742 | D35: Text | E35: 1652 | F35: 89 | G35: 357 | H35: 29736 | I35: 28771 | J35: 215 | K35: #TeslaCoInnovation | L35: NA | M35: NA | N35: FSDUpdate | O35: =((E35+F35+G35)/H35)*100 -> 7.055421 | P35: =IF(AND(C35>=$W$2,C35<=$X$2),"During","Before") -> Before | Q35: =AVERAGEIF(P35:P334,"Before",O35) -> 15.798918 | R35: =AVERAGEIF(P35:P334,"During",O35) -> 10.661912 | S35: =(R35-Q35)/Q35 -> -0.32514923
A36: P035 | B36: Instagram | C36: 45626 | D36: Video | E36: 3775 | F36: 16 | G36: 239 | H36: 33975 | I36: 33310 | J36: 271 | K36: #FutureOfDriving | L36: NA | M36: NA | N36: ModelYCampaign | O36: =((E36+F36+G36)/H36)*100 -> 11.861663 | P36: =IF(AND(C36>=$W$2,C36<=$X$2),"During","Before") -> Before | Q36: =AVERAGEIF(P36:P335,"Before",O36) -> 15.8349 | R36: =AVERAGEIF(P36:P335,"During",O36) -> 10.661912 | S36: =(R36-Q36)/Q36 -> -0.32668269
A37: P036 | B37: Instagram | C37: 45766 | D37: Story | E37: 4518 | F37: 285 | G37: 383 | H37: 67770 | I37: 67621 | J37: 31 | K37: #EVRevolution | L37: NA | M37: NA | N37: ModelYCampaign | O37: =((E37+F37+G37)/H37)*100 -> 7.6523535 | P37: =IF(AND(C37>=$W$2,C37<=$X$2),"During","Before") -> Before | Q37: =AVERAGEIF(P37:P336,"Before",O37) -> 15.851318 | R37: =AVERAGEIF(P37:P336,"During",O37) -> 10.661912 | S37: =(R37-Q37)/Q37 -> -0.32738009
A38: P037 | B38: Facebook | C38: 45663 | D38: Carousel | E38: 3024 | F38: 925 | G38: 350 | H38: 24192 | I38: 23518 | J38: 36 | K38: #EVRevolution | L38: NA | M38: NA | N38: ModelYCampaign | O38: =((E38+F38+G38)/H38)*100 -> 17.770337 | P38: =IF(AND(C38>=$W$2,C38<=$X$2),"During","Before") -> Before | Q38: =AVERAGEIF(P38:P337,"Before",O38) -> 15.885338 | R38: =AVERAGEIF(P38:P337,"During",O38) -> 10.661912 | S38: =(R38-Q38)/Q38 -> -0.32882059
A39: P038 | B39: YouTube | C39: 45705 | D39: Reel | E39: 3138 | F39: 123 | G39: 291 | H39: 28242 | I39: 27550 | J39: 87 | K39: #TeslaCoInnovation | L39: NA | M39: NA | N39: SustainabilityDrive | O39: =((E39+F39+G39)/H39)*100 -> 12.577013 | P39: =IF(AND(C39>=$W$2,C39<=$X$2),"During","Before") -> Before | Q39: =AVERAGEIF(P39:P338,"Before",O39) -> 15.877484 | R39: =AVERAGEIF(P39:P338,"During",O39) -> 10.661912 | S39: =(R39-Q39)/Q39 -> -0.32848858
A40: P039 | B40: Facebook | C40: 45621 | D40: Image | E40: 3564 | F40: 629 | G40: 177 | H40: 60588 | I40: 59627 | J40: 92 | K40: #TeslaCoInnovation | L40: NA | M40: NA | O40: =((E40+F40+G40)/H40)*100 -> 7.2126494 | P40: =IF(AND(C40>=$W$2,C40<=$X$2),"During","Before") -> Before | Q40: =AVERAGEIF(P40:P339,"Before",O40) -> 15.891294 | R40: =AVERAGEIF(P40:P339,"During",O40) -> 10.661912 | S40: =(R40-Q40)/Q40 -> -0.32907212
...

Sheet Task 5.2
A3: Campaign_Name | B3: Average of ROI
A4: CybertruckLaunch | B4: 0.044517296
A5: FSDUpdate | B5: 0.03278738
A6: ModelYCampaign | B6: 0.030899518
A7: SustainabilityDrive | B7: 0.053203004
A8: (blank)
A9: Grand Total | B9: 0.0403518

Sheet Task 5.3
A3: Campaign_Name | B3: Average of Follower_Growth_Rate
A4: CybertruckLaunch | B4: 0.92800257
A5: FSDUpdate | B5: 0.90210666
A6: ModelYCampaign | B6: 0.54649907
A7: SustainabilityDrive | B7: 0.57625321
A8: (blank)
A9: Grand Total | B9: 0.73821538

Sheet Task 6
A3: Average of Follower_Growth_Rate | B3: Column Labels
A4: Week_start_Date | B4: Facebook | C4: Instagram | D4: Twitter | E4: YouTube | F4: (blank) | G4: Grand Total
A5: 45446 | B5: 2.3491349 | C5: 0.30428616 | D5: 0.28263209 | E5: 0.27557542 | G5: 0.80290714
A6: 45453 | B6: 0.40530082 | C6: 1.0517322 | D6: 0.073128443 | E6: 0.24016739 | G6: 0.44258221
A7: 45460 | B7: 0.81535847 | C7: 0.19542791 | D7: 1.0551445 | E7: 0.0880238 | G7: 0.53848868
A8: 45467 | B8: 6.3510173 | C8: 1.7636833 | D8: 0.27980605 | E8: -0.028860774 | G8: 2.0914115
A9: 45474 | B9: 0.029088265 | C9: -0.052211602 | D9: 0.43037694 | E9: 0.080050669 | G9: 0.12182607
A10: 45481 | B10: 0.12276812 | C10: 2.8717174 | D10: 0.14032477 | E10: 0.21994574 | G10: 0.838689
A11: 45488 | B11: -0.049009939 | C11: 1.1967386 | D11: 0.18982133 | E11: 0.10211701 | G11: 0.35991676
A12: 45495 | B12: 0.32572738 | C12: 0.033557614 | D12: 0.66371458 | E12: 0.10340418 | G12: 0.28160094
A13: 45502 | B13: -0.073097735 | C13: 2.2861731 | D13: 0.51986619 | E13: 0.76001216 | G13: 0.87323843
A14: 45509 | B14: -0.15755714 | C14: 0.080371169 | D14: 0.072889861 | E14: 0.09948542 | G14: 0.023797326
A15: 45516 | B15: 0.43366319 | C15: 0.27085701 | D15: 0.0085080355 | E15: 1.0113483 | G15: 0.43109413
A16: 45523 | B16: 0.5752376 | C16: 0.023352712 | D16: 0.88256341 | E16: 0.2172844 | G16: 0.42460953
... A54: 45789 | B54: 0.11156187 | C54: 0.35361872 | D54: 0.058952702 | E54: -0.40819787 | G54: 0.028983854
A55: (blank)
A56: Grand Total | B56: 0.54649907 | C56: 0.57625321 | D56: 0.92800257 | E56: 0.90210666 | G56: 0.73821538

Sheet Task 6.1
A3: Week_Start_Date | B3: Average of Followers_Gain
A4: 45446 | B4: 888.5
A5: 45453 | B5: 745
A6: 45460 | B6: 976.75
A7: 45467 | B7: 752.75
A8: 45474 | B8: 323.25
A9: 45481 | B9: 760.5
A10: 45488 | B10: 567.5
A11: 45495 | B11: 688.25
A12: 45502 | B12: 548.25
A13: 45509 | B13: 200.5
A14: 45516 | B14: 932
A15: 45523 | B15: 747.25
... A53: 45789 | B53: 498.75
A54: (blank)
A55: Grand Total | B55: 800.525

Sheet Task 6.2
A3: Week_Start_Date | B3: Sum of Follower_Growth_Rate
A4: 45446 | B4: 3.2116286
A5: 45453 | B5: 1.7703289
A6: 45460 | B6: 2.1539547
A7: 45467 | B7: 8.3656458
A8: 45474 | B8: 0.48730427
A9: 45481 | B9: 3.354756
A10: 45488 | B10: 1.439667
A11: 45495 | B11: 1.1264038
A12: 45502 | B12: 3.4929537
A13: 45509 | B13: 0.095189305
A14: 45516 | B14: 1.7243765
A15: 45523 | B15: 1.6984381
... A53: 45789 | B53: 0.11593541
A54: (blank)
A55: Grand Total | B55: 147.64308

Sheet Task 6.3
A1: Column1 | B1: Ad_Spend | C1: Follower_Growth_Rate
A2: Ad_Spend | B2: 1
A3: Follower_Growth_Rate | B3: -0.6277813 | C3: 1

Sheet Video Link
F5: Project Video Link : https://drive.google.com/file/d/15Odt2I0_4xsa_THDe3CgpN5BrbHSeMrs/view?usp=sharing
